Workbook
Name Applicatino_response: [1]Usage!$GE$2:$GE$7
Name Application_Age: '[1]Application Info'!$GF$2:$GF$7
Name Application_Age: '[1]Application Info'!$GF$2:$GF$7
Name Application_Age: '[1]Application Info'!$GF$2:$GF$7
Name Application_Age: '[1]Application Info'!$GF$2:$GF$7
Name Application_Age: '[1]Application Info'!$GF$2:$GF$7
Name Application_Age: '[1]Application Info'!$GF$2:$GF$7
Name Application_Age: '[1]Application Info'!$GF$2:$GF$7
Name Application_Age: 'Application Info'!$GF$2:$GF$7
Name Application_Complexity: '[1]Technical Info'!$GH$2:$GH$6
Name Application_Criticality: '[1]Business Info'!$GE$2:$GE$6
Name Application_Dev_Tech: '[1]Technical Info'!$GE$2:$GE$60
Name Application_last_accessed: [1]Maintenance!$GD$2:$GD$5
Name Application_Load_Variation: [1]Usage!$GG$2:$GG$4
Name Application_Type_EY: '[1]Application Info'!$GE$2:$GE$6
Name Application_Type_EY: '[1]Application Info'!$GE$2:$GE$6
Name Application_Type_EY: '[1]Application Info'!$GE$2:$GE$6
Name Application_Type_EY: '[1]Application Info'!$GE$2:$GE$6
Name Application_Type_EY: '[1]Application Info'!$GE$2:$GE$6
Name Application_Type_EY: '[1]Application Info'!$GE$2:$GE$6
Name Application_Type_EY: '[1]Application Info'!$GE$2:$GE$6
Name Application_Type_EY: 'Application Info'!$GE$2:$GE$6
Name Architecture_Style: '[1]Technical Info'!$GB$2:$GB$10
Name Audience: [1]Usage!$GC$2:$GC$5
Name Business_change_3_months: [1]Maintenance!$GC$2:$GC$7
Name business_layer: '[1]Technical Platforms'!$GB$2:$GB$91
Name Business_User_satisfication: '[1]Business Info'!$GI$2:$GI$6
Name Criticality_Interface: '[1]Technical Info'!$GG$2:$GG$9
Name data_layer: '[1]Technical Platforms'!$GC$2:$GC$58
Name Functional_Fitness: '[1]Business Info'!$GH$2:$GH$6
Name hardware_plat: '[1]Technical Platforms'!$GD$2:$GD$74
Name Infosec_Classification: '[1]Business Info'!$GF$2:$GF$6
Name Integration_architecture: '[1]Technical Info'!$GD$2:$GD$15
Name IT_portfolio: '[1]Application Info'!$GD$2:$GD$6
Name IT_portfolio: '[1]Application Info'!$GD$2:$GD$6
Name IT_portfolio: '[1]Application Info'!$GD$2:$GD$6
Name IT_portfolio: '[1]Application Info'!$GD$2:$GD$6
Name IT_portfolio: '[1]Application Info'!$GD$2:$GD$6
Name IT_portfolio: '[1]Application Info'!$GD$2:$GD$6
Name IT_portfolio: '[1]Application Info'!$GD$2:$GD$6
Name IT_portfolio: 'Application Info'!$GD$2:$GD$6
Name Line_Of_Business: '[1]Business Info'!$GC$2:$GC$2
Name Names: #REF!
Name Namess: #REF!
Name No_of_App_Users: [1]Usage!$GB$2:$GB$11
Name operating_sys: '[1]Technical Platforms'!$GE$2:$GE$38
Name Pace_Layer: '[1]Technical Info'!$GI$2:$GI$7
Name Presentation_Layer: '[1]Technical Info'!$GC$2:$GC$10
Name Programmin_tech: '[1]Technical Platforms'!$GF$2:$GF$67
Name Red_box: '[1]Application Info'!$GC$2:$GC$7
Name Red_box: '[1]Application Info'!$GC$2:$GC$7
Name Red_box: '[1]Application Info'!$GC$2:$GC$7
Name Red_box: '[1]Application Info'!$GC$2:$GC$7
Name Red_box: '[1]Application Info'!$GC$2:$GC$7
Name Red_box: '[1]Application Info'!$GC$2:$GC$7
Name Red_box: '[1]Application Info'!$GC$2:$GC$7
Name Red_box: 'Application Info'!$GC$2:$GC$7
Name Region: '[1]Application Info'!$GB$2:$GB$6
Name Region: '[1]Application Info'!$GB$2:$GB$6
Name Region: '[1]Application Info'!$GB$2:$GB$6

Sheet Application Info
A1: Tool Id | B1: Business Unit Name | C1: Application Name | D1: Application ID | E1: Application Name | F1: Application Description | G1: Region | H1: Hosting | I1: IT Portfolio | J1: IT Portfolio Owner | K1: Application Business SME | L1: Application Source | M1: Application Age (In Years) | N1: Application Status | O1: Vendor Name | P1: EOL (End of Life) for product | Q1: EOVS (End of Vendor Support) | FY1: Field Names | GB1: <b>Region</b> | GC1: <strong>Hosting</strong> | GD1: <b>IT Portfolio</b> | GE1: <b>Application Source</b> | GF1: <b>Application Age (In Years)</b> | GG1: <strong>Application Status</strong>
B2: Surgir | C2: SAP by Design | D2: APMF0001067852 | E2: =C2 -> SAP by Design | F2: Sistema ERP SAP para la gestión de procesos administrativos, financieros, contables y operativos. URL: https://my430488.businessbydesign.cloud.sap/sap/public/ap/ui/repository/SAP_UI/HTMLOBERON5/client.html | G2: Azure | H2: 5. SaaS | I2: Enterprise App | K2: =Stakeholders!E2 -> RENZO ALFREDO HUAYLLASCO CÁCERES | L2: Vendor Custom | M2: 0-3 yrs | N2: In Active | O2: =LOOKUP(C2,[2]APMT_Detalle!$B$82:$B$521,[2]APMT_Detalle!$S$2:$S$521) -> Santander Digital Services | R2: =LOOKUP(C2,[2]APMT_Detalle!$B$2:$B$521,[2]APMT_Detalle!$AP$2:$AP$521) -> External | FY2: ICTO_ID_App | GB2: Local Country | GC2: 1. Cloud | GD2: Infrastructure | GE2: COTS OOB | GF2: 0-3 yrs | GG2: Decommissioned
B3: Surgir | C3: App Surgir | D3: APMF0001066860 | E3: =C3 -> App Surgir | F3: Aplicativo utilizado por la red comercial para el ingreso de las solicitudes de créditos. | G3: Local Country | H3: 3. Hybrid cloud | I3: IT Application | K3: =Stakeholders!E3 -> RENZO ALFREDO HUAYLLASCO CÁCERES | L3: In House Developed | N3: In Active | O3: =LOOKUP(C3,[2]APMT_Detalle!$B$82:$B$521,[2]APMT_Detalle!$S$2:$S$521) -> #N/A | R3: =LOOKUP(C3,[2]APMT_Detalle!$B$2:$B$521,[2]APMT_Detalle!$AP$2:$AP$521) -> External | FY3: Business_Solution_App | GB3: US | GC3: 2. Desktop | GD3: Security | GE3: COTS Customized | GF3: 4-6 yrs | GG3: Duplicate
B4: Surgir | C4: App Cliente | D4: APMF0001065929 | E4: =C4 -> App Cliente | F4: App Cliente es una aplicación móvil que centraliza servicios bancarios y financieros, permitiendo a los usuarios gestionar su dinero, realizar transacciones, consultar saldos, pagar servicios desde un smartphone, ofreciendo comodidad, seguridad y ahorro de tiempo al reducir la necesidad de ir a oficinas físicas. | G4: Local Country | H4: 3. Hybrid cloud | I4: Enterprise App | K4: =Stakeholders!E4 -> YELTSIN ANTONY ALAN SOTELO CAMONES | L4: In House Developed | N4: In Active | O4: =LOOKUP(C4,[2]APMT_Detalle!$B$82:$B$521,[2]APMT_Detalle!$S$2:$S$521) -> #N/A | R4: =LOOKUP(C4,[2]APMT_Detalle!$B$2:$B$521,[2]APMT_Detalle!$AP$2:$AP$521) -> External | FY4: Business_Solution_Description | GB4: AWS | GC4: 3. Hybrid cloud | GD4: End User Computing | GE4: Vendor Custom | GF4: 7-10 yrs | GG4: In-Scope
B5: Surgir | C5: AMLUpdate - Name Screening | D5: APMF0001049960 | E5: =C5 -> AMLUpdate - Name Screening | F5: Plataforma para el cumplimiento de FCC utilizada para el cruce y migrar a One FCC verificación de listas de sanciones, personas y entidades restringidas, consumido por los procesos de AML del negocio de Surgir a través de: - API llamada por los procesos que requieren consultas de AML. - Portal donde el área usuaria local (PLAFT) consulta el histórico de llamadas. URL: https://new.amlupdate.com/ | G5: Mexico | H5: 8. On-Premise | K5: =Stakeholders!E5 -> RENZO ALFREDO HUAYLLASCO CÁCERES | L5: Vendor Custom | N5: In Active | O5: GESINTEL | R5: =LOOKUP(C5,[2]APMT_Detalle!$B$2:$B$521,[2]APMT_Detalle!$AP$2:$AP$521) -> #N/A | FY5: Red_box | GB5: Azure | GC5: 5. SaaS | GD5: Enterprise App | GE5: Not Applicable | GF5: >15 yrs | GG5: Out-of Scope
B6: Surgir | C6: Portal Web Público | D6: APMF0001022615 | E6: =C6 -> Portal Web Público | F6: Sitio web público del negocio de Surgir, que facilita informarción institucional de la compañía, muestra el catálogo de productos y permite a los clientes solicitar una llamada para iniciar su contratación. Es un sitio no transaccional. Se migrará a Landing Zone. https://www.surgir.com.pe/ | G6: Local Country | H6: 8. On-Premise | K6: =Stakeholders!E6 -> RENZO ALFREDO HUAYLLASCO CÁCERES | L6: In House Developed | N6: In Active | O6: =LOOKUP(C6,[2]APMT_Detalle!$B$82:$B$521,[2]APMT_Detalle!$S$2:$S$521) -> Santander Digital Services | R6: =LOOKUP(C6,[2]APMT_Detalle!$B$2:$B$521,[2]APMT_Detalle!$AP$2:$AP$521) -> Internal Cloud | FY6: IT_portfolio | GB6: Mexico | GC6: 6. Sharepoint | GD6: IT Application | GE6: In House Developed | GF6: Not Applicable | GG6: In Active
B7: Surgir | C7: Anura | D7: APMF0001022614 | E7: =C7 -> Anura | F7: Servicio de atención telefónica en la nube del proveedor ANURA, incluye el personal. Es un SaaS arrendado al proveedor. | G7: Local Country | H7: 5. SaaS | K7: =Stakeholders!E7 -> RENZO ALFREDO HUAYLLASCO CÁCERES | L7: COTS OOB | N7: In Active | O7: =LOOKUP(C7,[2]APMT_Detalle!$B$82:$B$521,[2]APMT_Detalle!$S$2:$S$521) -> #N/A | R7: =LOOKUP(C7,[2]APMT_Detalle!$B$2:$B$521,[2]APMT_Detalle!$AP$2:$AP$521) -> External | FY7: IT_portfolio_Owner | GB7: España | GC7: 7.Vendor sit | GF7: Not Available | GG7: Already on Cloud
B8: Surgir | C8: ERP Contanet | D8: APMF0001022612 | E8: =C8 -> ERP Contanet | F8: Sistema ERP utilizado por Surgir, el negocio de microemprendedores de Santander en Perú, para la gestión contable, financiera y administrativa. Permite registrar y controlar las operaciones del negocio, asegurando la trazabilidad, la integridad de la información y el cumplimiento de las normativas locales y corporativas. La BBDD se encuentra en la Nube de SURGIR, se encuentra en planes de migración a SAP Contanet. | G8: Azure | H8: 5. SaaS | K8: =Stakeholders!E8 -> RENZO ALFREDO HUAYLLASCO CÁCERES | L8: In House Developed | N8: In Active | O8: =LOOKUP(C8,[2]APMT_Detalle!$B$82:$B$521,[2]APMT_Detalle!$S$2:$S$521) -> Vector | R8: =LOOKUP(C8,[2]APMT_Detalle!$B$2:$B$521,[2]APMT_Detalle!$AP$2:$AP$521) -> Internal Cloud | FY8: Application_SME | GC8: 8. On-Premise | GG8: To be Retired
B9: Surgir | C9: Datalake | D9: APMF0001022613 | E9: =C9 -> Datalake | F9: Datalake en el que se almacenan datos generados por el core COBIS para generar informes regulatorios de pagos. Se encuentra en la Nube de SURGIR y se encuentra en el plan de migración a Landing Zone. | G9: Local Country | H9: 3. Hybrid cloud | K9: =Stakeholders!E9 -> RENZO ALFREDO HUAYLLASCO CÁCERES | L9: In House Developed | N9: In Active | O9: =LOOKUP(C9,[2]APMT_Detalle!$B$82:$B$521,[2]APMT_Detalle!$S$2:$S$521) -> Santander Digital Services | R9: =LOOKUP(C9,[2]APMT_Detalle!$B$2:$B$521,[2]APMT_Detalle!$AP$2:$AP$521) -> External | FY9: Application_Type_EY
B10: Surgir | C10: Cobis | D10: APMF0001022611 | E10: =C10 -> Cobis | F10: Sistema Core Bancario modular permite gestionar los productos y servicios financieros del negocio Surgir (cuentas de ahorro, seguros de ahorro, depósitos a plazo y créditos), dirigidas a negocios de emprendedores unipersonales. Es un SaaS en AWS del propio proveedro COBIS TOPAZ. URL: https://www.web.surgir-pe.cobiscloud.com/CWC/services/cobis/web/bank/views/commons/login.html? | G10: AWS | H10: 3. Hybrid cloud | K10: =Stakeholders!E10 -> RENZO ALFREDO HUAYLLASCO CÁCERES | L10: Vendor Custom | N10: In Active | O10: =LOOKUP(C10,[2]APMT_Detalle!$B$82:$B$521,[2]APMT_Detalle!$S$2:$S$521) -> Sentinel Peru | R10: =LOOKUP(C10,[2]APMT_Detalle!$B$2:$B$521,[2]APMT_Detalle!$AP$2:$AP$521) -> External | FY10: Application_Age
B11: Santander Fondos Colectivos | C11: Emblue | D11: APMF0001067771 | E11: =C11 -> Emblue | F11: Servicio de Plantillas para envío de correo electrónico del proveedor Emblue, que permite la captura de acciones del usuario final (abrir mensaje - similar a Danna Connect) | G11: Local Country | H11: 7.Vendor sit | K11: =Stakeholders!E11 -> Luis Alberto Barandiaran | L11: Vendor Custom | N11: In Active | O11: =LOOKUP(C11,[2]APMT_Detalle!$B$82:$B$521,[2]APMT_Detalle!$S$2:$S$521) -> Vector | R11: =LOOKUP(C11,[2]APMT_Detalle!$B$2:$B$521,[2]APMT_Detalle!$AP$2:$AP$521) -> Internal Cloud | FY11: TOPAZ_Indicator
B12: Santander Fondos Colectivos | C12: Facephi | D12: APMF0001067770 | E12: =C12 -> Facephi | F12: Servicio de validación de morfología de documentos de identidad, validación de identidad por biometría, y servicio de firma digital del proveedor Facephi, utilizado por la aplicación Core Santo. | G12: Local Country | H12: 7.Vendor sit | K12: =Stakeholders!E12 -> Luis Alberto Barandiaran | L12: Vendor Custom | N12: In Active | O12: =LOOKUP(C12,[2]APMT_Detalle!$B$82:$B$521,[2]APMT_Detalle!$S$2:$S$521) -> Vector | R12: =LOOKUP(C12,[2]APMT_Detalle!$B$2:$B$521,[2]APMT_Detalle!$AP$2:$AP$521) -> On Premises | FY12: End_of_life
B13: Santander Fondos Colectivos | C13: Mapfre | D13: APMF0001067527 | E13: =C13 -> Mapfre | F13: Servicio de emisión y gestión de seguros con el proveedor Seguros Mapfre (API y Plataforma de Servicios). | G13: Local Country | H13: 5. SaaS | K13: =Stakeholders!E13 -> LUIS BOULLON GARCIA | L13: In House Developed | N13: In Active | O13: =LOOKUP(C13,[2]APMT_Detalle!$B$82:$B$521,[2]APMT_Detalle!$S$2:$S$521) -> Externo | R13: =LOOKUP(C13,[2]APMT_Detalle!$B$2:$B$521,[2]APMT_Detalle!$AP$2:$AP$521) -> On Premises | FY13: End_of_Vendor_Support
B14: Santander Fondos Colectivos | C14: Tracklink | D14: APMF0001067523 | E14: =C14 -> Tracklink | F14: Servicio (API) de instalación y gestión de GPS con el proveedor Tracklink (Instalación de GPS a los vehiculos). | G14: Local Country | H14: 7.Vendor sit | K14: =Stakeholders!E14 -> LUIS BOULLON GARCIA | L14: Vendor Custom | N14: In Active | O14: =LOOKUP(C14,[2]APMT_Detalle!$B$82:$B$521,[2]APMT_Detalle!$S$2:$S$521) -> MICROSOFT | R14: =LOOKUP(C14,[2]APMT_Detalle!$B$2:$B$521,[2]APMT_Detalle!$AP$2:$AP$521) -> Internal Cloud
B15: Santander Fondos Colectivos | C15: Docuclass | D15: APMF0001067521 | E15: =C15 -> Docuclass | F15: Servicio de administración de documentos integrado del proveedor DocuClass. | G15: Local Country | H15: 8. On-Premise | K15: =Stakeholders!E15 -> LUIS BOULLON GARCIA | L15: In House Developed | N15: In Active | O15: =LOOKUP(C15,[2]APMT_Detalle!$B$82:$B$521,[2]APMT_Detalle!$S$2:$S$521) -> Santander Digital Services | R15: =LOOKUP(C15,[2]APMT_Detalle!$B$2:$B$521,[2]APMT_Detalle!$AP$2:$AP$521) -> External
B16: Santander Fondos Colectivos | C16: Diloo | D16: APMF0001067520 | E16: =C16 -> Diloo | F16: Servicio de envío de mensajería por SMS del proveedor Diloo. | G16: US | H16: 7.Vendor sit | K16: =Stakeholders!E16 -> LUIS BOULLON GARCIA | L16: Vendor Custom | N16: In Active | O16: =LOOKUP(C16,[2]APMT_Detalle!$B$82:$B$521,[2]APMT_Detalle!$S$2:$S$521) -> Santander Digital Services | R16: =LOOKUP(C16,[2]APMT_Detalle!$B$2:$B$521,[2]APMT_Detalle!$AP$2:$AP$521) -> External
B17: Santander Fondos Colectivos | C17: Izipay Pagos en línea | D17: APMF0001067419 | E17: =C17 -> Izipay Pagos en línea | F17: Servicio de pagos en línea del proveedor Izipay | G17: Local Country | H17: 3. Hybrid cloud | K17: =Stakeholders!E17 -> Luis Alberto Barandiaran | L17: COTS Customized | N17: In Active | O17: =LOOKUP(C17,[2]APMT_Detalle!$B$82:$B$521,[2]APMT_Detalle!$S$2:$S$521) -> Externo | R17: =LOOKUP(C17,[2]APMT_Detalle!$B$2:$B$521,[2]APMT_Detalle!$AP$2:$AP$521) -> On Premises
B18: Santander Fondos Colectivos | C18: IBK Recaudación | D18: APMF0001067418 | E18: =C18 -> IBK Recaudación | F18: Servicio de recaudación bancaria del proveedor Banco INTERBANK (Archivo con información enviado por FTP para la recaudación de Fondos Colectivos). | G18: Local Country | H18: 8. On-Premise | K18: =Stakeholders!E18 -> Luis Alberto Barandiaran | L18: COTS Customized | N18: In Active | O18: =LOOKUP(C18,[2]APMT_Detalle!$B$82:$B$521,[2]APMT_Detalle!$S$2:$S$521) -> Externo | R18: =LOOKUP(C18,[2]APMT_Detalle!$B$2:$B$521,[2]APMT_Detalle!$AP$2:$AP$521) -> On Premises
B19: Santander Fondos Colectivos | C19: SAP by Design | D19: APMF0001067032 | E19: =C19 -> SAP by Design | F19: Sistema ERP SAP para la gestión de procesos administrativos, financieros, contables y operativos. URL: https://my430488.businessbydesign.cloud.sap/sap/public/ap/ui/repository/SAP_UI/HTMLOBERON5/client.html | G19: Mexico | H19: 5. SaaS | K19: =Stakeholders!E19 -> Luis Alberto Barandiaran | L19: Vendor Custom | N19: In Active | O19: =LOOKUP(C19,[2]APMT_Detalle!$B$82:$B$521,[2]APMT_Detalle!$S$2:$S$521) -> Santander Digital Services | R19: =LOOKUP(C19,[2]APMT_Detalle!$B$2:$B$521,[2]APMT_Detalle!$AP$2:$AP$521) -> External
B20: Santander Fondos Colectivos | C20: Portal Web Público | D20: APMF0001065693 | E20: =C20 -> Portal Web Público | F20: Página Web Pública (Solo es informativo), solución táctica, en base al desarrollo de surgir 2024, alojado en Azure SURGIR, para realizar cambios es necesario la aprobación del comité. URL: http://www.santanderfondoscolectivos.com.pe/ | G20: Mexico | H20: 8. On-Premise | K20: =Stakeholders!E20 -> Luis Alberto Barandiaran | L20: In House Developed | N20: In Active | O20: =LOOKUP(C20,[2]APMT_Detalle!$B$82:$B$521,[2]APMT_Detalle!$S$2:$S$521) -> Santander Digital Services | R20: =LOOKUP(C20,[2]APMT_Detalle!$B$2:$B$521,[2]APMT_Detalle!$AP$2:$AP$521) -> Internal Cloud
B21: Santander Fondos Colectivos | C21: AMLUpdate - Name Screening | D21: APMF0001055717 | E21: =C21 -> AMLUpdate - Name Screening | F21: Plataforma para el cumplimiento de FCC utilizada para el cruce y migrar a One FCC verificación de listas de sanciones, personas y entidades restringidas, consumido por los procesos de AML del negocio de Fondos Colectivos a través de: - API llamada por los procesos que requieren consultas de AML. - Portal donde el área usuaria local (PLAFT) consulta el histórico de llamadas. URL: https://new.amlupdate.com/ | G21: Local Country | H21: 5. SaaS | K21: =Stakeholders!E21 -> ALONSO GUILLERMO SERRANO CARMONA | L21: In House Developed | N21: In Active | O21: GESINTEL | R21: =LOOKUP(C21,[2]APMT_Detalle!$B$2:$B$521,[2]APMT_Detalle!$AP$2:$AP$521) -> #N/A
B22: Santander Fondos Colectivos | C22: Santo | D22: APMF0001045007 | E22: =C22 -> Santo | F22: Sistema principal de Fondos Colectivos provisto por el proveedor SoftTek, integrado a Azure AD, base de datos Azure SQL (Costo de Infra + Costo de Servicio). - Core: Sistema utilizado por los equipos de operaciones y contabilidad - Front: Sistema utilizado por los ejecutivos de ventas y operaciones - Plaft: Sistema utilizado por el equipo de Plaft para la configuración de reglas y monitoreo de transacciones - Firma: Web donde los clientes se autentican con su usuario, documento de identidad e identificación biométrica para firmar digitalmente los documentos de la empresa - Pagos: Web donde los clientes visualizan los pagos pendientes a realizar y efectúan los pagos de sus obligaciones pendientes - Reclamos: Sistema utilizado por el equipo de operaciones para la gestión de requerimientos y reclamos | G22: Local Country | H22: 3. Hybrid cloud | K22: =Stakeholders!E22 -> LUIS BOULLON GARCIA | L22: COTS Customized | N22: In Active | O22: =LOOKUP(C22,[2]APMT_Detalle!$B$82:$B$521,[2]APMT_Detalle!$S$2:$S$521) -> Santander Digital Services | R22: =LOOKUP(C22,[2]APMT_Detalle!$B$2:$B$521,[2]APMT_Detalle!$AP$2:$AP$521) -> External
B23: SCIB Perú | C23: Nuevo Office Banking | D23: APMF0001038152 | E23: =C23 -> Nuevo Office Banking | F23: Herramienta del nuevo OOBB alojada en la LZONE. | G23: US | H23: 5. SaaS | K23: =Stakeholders!E23 -> ALFREDO LLONA ARIS | L23: In House Developed | N23: In Active | O23: =LOOKUP(C23,[2]APMT_Detalle!$B$82:$B$521,[2]APMT_Detalle!$S$2:$S$521) -> Externo | R23: =LOOKUP(C23,[2]APMT_Detalle!$B$2:$B$521,[2]APMT_Detalle!$AP$2:$AP$521) -> On Premises
B24: SCIB Perú | C24: CEEFFC | D24: APMF0001021795 | E24: =C24 -> CEEFFC | F24: Central de Estados financieros de clientes (Interno), Alberga los estados de cuenta de clientes gestionados por el área comercial para el área de Riesgos. | G24: Mexico | H24: 8. On-Premise | K24: =Stakeholders!E24 -> LUIS CONTRERAS AVILA | L24: In House Developed | N24: In Active | O24: =LOOKUP(C24,[2]APMT_Detalle!$B$82:$B$521,[2]APMT_Detalle!$S$2:$S$521) -> #N/A | R24: =LOOKUP(C24,[2]APMT_Detalle!$B$2:$B$521,[2]APMT_Detalle!$AP$2:$AP$521) -> External
B25: SCIB Perú | C25: Lbtr | D25: APMF0001013067 | E25: =C25 -> Lbtr | F25: Gestión y realización de transferencias interbancarias BCRP. | G25: Local Country | H25: 8. On-Premise | K25: =Stakeholders!E25 -> ALFREDO LLONA ARIS | L25: Vendor Custom | N25: In Active | O25: =LOOKUP(C25,[2]APMT_Detalle!$B$82:$B$521,[2]APMT_Detalle!$S$2:$S$521) -> Externo | R25: =LOOKUP(C25,[2]APMT_Detalle!$B$2:$B$521,[2]APMT_Detalle!$AP$2:$AP$521) -> On Premises
B26: SCIB Perú | C26: Cash Nexus | D26: APMF0001013065 | E26: =C26 -> Cash Nexus | F26: Solución tecnológica que actúa como capa de integración entre los sistemas internos del banco y la plataforma global Cash Nexus. Facilita la comunicación y el intercambio seguro de información relacionada con pagos, cuentas y servicios de tesorería internacional. El middleware gestiona el enrutamiento, transformación y validación de mensajes entre las aplicaciones locales y el ecosistema Cash Nexus, asegurando la interoperabilidad, la trazabilidad de las transacciones y el cumplimiento de los estándares corporativos de seguridad y conectividad. Propósito principal: Garantizar una conexión eficiente, segura y estandarizada entre los sistemas bancarios locales y la plataforma global Cash Nexus, optimizando la integración de servicios de tesorería y pagos internacionales. Usuarios principales: Equipos de Tesorería, Operaciones, Tecnología y Banca Transaccional. | G26: Local Country | H26: 3. Hybrid cloud | K26: =Stakeholders!E26 -> ALEXANDRA DIAZ FIGUEROA | L26: In House Developed | N26: In Active | O26: Softtek | R26: =LOOKUP(C26,[2]APMT_Detalle!$B$2:$B$521,[2]APMT_Detalle!$AP$2:$AP$521) -> External
B27: SCIB Perú | C27: Host to Host | D27: APMF0001013066 | E27: =C27 -> Host to Host | F27: Servicio de GTB para que los clientes que se conectan a través de su plataforma puedan enviar la información de los pagos a ejecutar. | G27: Local Country | H27: 8. On-Premise | K27: =Stakeholders!E27 -> JAVIER SAVAGE ZIMMERMANN | L27: In House Developed | N27: In Active | O27: =LOOKUP(C27,[2]APMT_Detalle!$B$82:$B$521,[2]APMT_Detalle!$S$2:$S$521) -> Externo | R27: =LOOKUP(C27,[2]APMT_Detalle!$B$2:$B$521,[2]APMT_Detalle!$AP$2:$AP$521) -> On Premises
B28: SCIB Perú | C28: Sistema Office Banking | D28: APMF0001013063 | E28: =C28 -> Sistema Office Banking | F28: Portal del banco Santander Perú que expone la banca privada de la organizacion. https://www.santander.com.pe/BSP/home/index2.html | G28: Azure | H28: 3. Hybrid cloud | K28: =Stakeholders!E28 -> ALEXANDRA DIAZ FIGUEROA | L28: In House Developed | N28: In Active | O28: =LOOKUP(C28,[2]APMT_Detalle!$B$82:$B$521,[2]APMT_Detalle!$S$2:$S$521) -> MICROSOFT | R28: =LOOKUP(C28,[2]APMT_Detalle!$B$2:$B$521,[2]APMT_Detalle!$AP$2:$AP$521) -> External
B29: Santander Consumer Perú | C29: Diloo | D29: APMF0001067859 | E29: =C29 -> Diloo | F29: SaaS para mensajeria hacia clientes mediante mensaje de SMS. https://dilootu.com | G29: US | H29: 7.Vendor sit | K29: =Stakeholders!E29 -> LUIS BOULLON GARCIA | N29: In Active | O29: =LOOKUP(C29,[2]APMT_Detalle!$B$82:$B$521,[2]APMT_Detalle!$S$2:$S$521) -> Santander Digital Services | R29: =LOOKUP(C29,[2]APMT_Detalle!$B$2:$B$521,[2]APMT_Detalle!$AP$2:$AP$521) -> External
B30: Santander Consumer Perú | C30: Plataforma de Facturacion Electronica | D30: APMF0001066833 | E30: =C30 -> Plataforma de Facturacion Electronica | F30: Plataforma de emisión de comprobantes a lo clientes que realizan pagos de sus créditos. | G30: AWS | H30: 8. On-Premise | K30: =Stakeholders!E30 -> JULIO EDUARDO NIÑO SUAREZ | L30: In House Developed | N30: In Active | O30: =LOOKUP(C30,[2]APMT_Detalle!$B$82:$B$521,[2]APMT_Detalle!$S$2:$S$521) -> Santander Digital Services | R30: =LOOKUP(C30,[2]APMT_Detalle!$B$2:$B$521,[2]APMT_Detalle!$AP$2:$AP$521) -> On Premises
B31: Santander Consumer Perú | C31: Contáctanos | D31: APMF0001066014 | E31: =C31 -> Contáctanos | F31: Página web para el registro de reclamos , requerimientos y quejas; que es usado por el Call Center. URL: http://180.194.16.208:81/#/reporte/contactanos | G31: Local Country | H31: 6. Sharepoint | K31: =Stakeholders!E31 -> RENZO ALFREDO HUAYLLASCO CÁCERES | L31: In House Developed | N31: In Active | O31: =LOOKUP(C31,[2]APMT_Detalle!$B$82:$B$521,[2]APMT_Detalle!$S$2:$S$521) -> Santander Digital Services | R31: =LOOKUP(C31,[2]APMT_Detalle!$B$2:$B$521,[2]APMT_Detalle!$AP$2:$AP$521) -> External
B32: Santander Consumer Perú | C32: Visor Cobranzas | D32: APMF0001062990 | E32: =C32 -> Visor Cobranzas | F32: Estado de Cliente morosos | G32: Local Country | H32: 6. Sharepoint | K32: =Stakeholders!E32 -> 0 | L32: In House Developed | N32: In Active | O32: =LOOKUP(C32,[2]APMT_Detalle!$B$82:$B$521,[2]APMT_Detalle!$S$2:$S$521) -> Santander Global Banking (GBM) | R32: =LOOKUP(C32,[2]APMT_Detalle!$B$2:$B$521,[2]APMT_Detalle!$AP$2:$AP$521) -> Internal Cloud
B33: Santander Consumer Perú | C33: Api Market | D33: APMF0001052967 | E33: =C33 -> Api Market | F33: Plataforma de APIS Públicas que serán expuestas a empresas del grupo Santander y otras empresas externas. Conjunto de apis , de evaluacion del cliente (devuelve si el cliente es apto para un credito vehicular y asi mismo inyecta en Santi) ; es una extencion de santi https://apimarket.santanderconsumer.com.pe/access-token/ https://apimarket.santanderconsumer.com.pe/api/int/v1/pre-assessment/evaluate https://apimarket.santanderconsumer.com.pe/api/int/v1/inquiry-disbursement/find-status | G33: Local Country | H33: 3. Hybrid cloud | K33: =Stakeholders!E33 -> RENZO ALFREDO HUAYLLASCO CÁCERES | L33: In House Developed | N33: In Active | O33: =LOOKUP(C33,[2]APMT_Detalle!$B$82:$B$521,[2]APMT_Detalle!$S$2:$S$521) -> #N/A | R33: =LOOKUP(C33,[2]APMT_Detalle!$B$2:$B$521,[2]APMT_Detalle!$AP$2:$AP$521) -> External
B34: Santander Consumer Perú | C34: AMLUpdate - Name Screening | D34: APMF0001049917 | E34: =C34 -> AMLUpdate - Name Screening | F34: Plataforma para el cumplimiento de FCC utilizada para el cruce y migrar a One FCC verificación de listas de sanciones, personas y entidades restringidas, consumido por los procesos de AML del negocio de Santander Consumer Perú a través de: - API llamada por los procesos que requieren consultas de AML. - Portal donde el área usuaria local (PLAFT) consulta el histórico de llamadas. URL: https://new.amlupdate.com/ | G34: Azure | H34: 5. SaaS | K34: =Stakeholders!E34 -> LUIS BOULLON GARCIA | L34: In House Developed | N34: In Active | O34: GESINTEL | R34: =LOOKUP(C34,[2]APMT_Detalle!$B$2:$B$521,[2]APMT_Detalle!$AP$2:$AP$521) -> #N/A
B35: Santander Consumer Perú | C35: Facturación Electrónica - Auto | D35: APMF0001042159 | E35: =C35 -> Facturación Electrónica - Auto | F35: Aplicación que permite la configuración y parametrización de la emisión, gestión y monitoreo de comprobantes electrónicos, ofreciendo una interfaz web para usuarios internos y externos. Facilita la trazabilidad del proceso de facturación y asegura el cumplimiento de los requisitos tributarios vigentes. Componentes Técnicos: - FE - Batch Emision. - FE - Batch Recepcion. - API de conexión a Base de Datos. - Batch de extracción de Datos. | G35: Mexico | H35: 8. On-Premise | K35: =Stakeholders!E35 -> LUIS BOULLON GARCIA | L35: In House Developed | N35: In Active | O35: =LOOKUP(C35,[2]APMT_Detalle!$B$82:$B$521,[2]APMT_Detalle!$S$2:$S$521) -> Vector | R35: =LOOKUP(C35,[2]APMT_Detalle!$B$2:$B$521,[2]APMT_Detalle!$AP$2:$AP$521) -> On Premises
B36: Santander Consumer Perú | C36: Portal Web Público | D36: APMF0001041864 | E36: =C36 -> Portal Web Público | F36: Portal web corporativo que ofrece información institucional, productos y servicios financieros para clientes de Santander Consumer Perú, permitiendo además la autogestión y solicitud en línea de créditos y otros servicios. La home solicita al usuario elegir a qué negocio quiere acceder: (1) Crédito vehicular -Auto-, transaccional: https://www.santanderconsumer.com.pe/autos (2) Soluciones crediticias -No auto- no transaccional: https://www.santanderconsumer.com.pe/personas | G36: Mexico | H36: 8. On-Premise | K36: =Stakeholders!E36 -> LUIS BOULLON GARCIA | L36: In House Developed | N36: In Active | O36: =LOOKUP(C36,[2]APMT_Detalle!$B$82:$B$521,[2]APMT_Detalle!$S$2:$S$521) -> Santander Digital Services | R36: =LOOKUP(C36,[2]APMT_Detalle!$B$2:$B$521,[2]APMT_Detalle!$AP$2:$AP$521) -> Internal Cloud
B37: Santander Consumer Perú | C37: SAP ByDesign - ERP | D37: APMF0001035655 | E37: =C37 -> SAP ByDesign - ERP | F37: Sistema ERP SAP para la gestión de procesos administrativos, financieros, contables y operativos del negocio de Auto. URL: https://my430488.businessbydesign.cloud.sap/sap/public/ap/ui/repository/SAP_UI/HTMLOBERON5/client.html | G37: Local Country | H37: 3. Hybrid cloud | K37: =Stakeholders!E37 -> LUIS BOULLON GARCIA | L37: Vendor Custom | N37: In Active | O37: =LOOKUP(C37,[2]APMT_Detalle!$B$82:$B$521,[2]APMT_Detalle!$S$2:$S$521) -> Santander Digital Services | R37: =LOOKUP(C37,[2]APMT_Detalle!$B$2:$B$521,[2]APMT_Detalle!$AP$2:$AP$521) -> External
B38: Santander Consumer Perú | C38: Bantotal - Core Bancario | D38: APMF0001035204 | E38: =C38 -> Bantotal - Core Bancario | F38: Core bancario Bantotal en modalidad SaaS, que da soporte a la actividad de créditos al consumo del negocio de Auto. URL: https://prod.scp.bantotal.com/bantotal/servlet/com.dlya.bantotal.hwelcome | G38: Azure | H38: 3. Hybrid cloud | K38: =Stakeholders!E38 -> LUIS BOULLON GARCIA | L38: Vendor Custom | N38: In Active | O38: Bantotal | R38: =LOOKUP(C38,[2]APMT_Detalle!$B$2:$B$521,[2]APMT_Detalle!$AP$2:$AP$521) -> External
B39: Santander Consumer Perú | C39: Motor de Crédito | D39: APMF0001035203 | E39: =C39 -> Motor de Crédito | F39: Motor de evaluación crediticia que analiza la capacidad y riesgo del solicitante para aprobación de créditos vehiculares del negocio Auto. | G39: Local Country | H39: 8. On-Premise | K39: =Stakeholders!E39 -> LUIS BOULLON GARCIA | L39: In House Developed | N39: In Active | O39: =LOOKUP(C39,[2]APMT_Detalle!$B$82:$B$521,[2]APMT_Detalle!$S$2:$S$521) -> Externo | R39: =LOOKUP(C39,[2]APMT_Detalle!$B$2:$B$521,[2]APMT_Detalle!$AP$2:$AP$521) -> On Premises
B40: Santander Consumer Perú | C40: Santi | D40: APMF0001035201 | E40: =C40 -> Santi | F40: Aplicación web que soporta el proceso originación y venta de créditos vehiculares, con agenda comercial para los ejecutivos comerciales del negocio. URL: https://nfsanti.santanderconsumer.com.pe/ | G40: Local Country | H40: 8. On-Premise | K40: =Stakeholders!E40 -> LUIS BOULLON GARCIA | L40: In House Developed | N40: In Active | O40: =LOOKUP(C40,[2]APMT_Detalle!$B$82:$B$521,[2]APMT_Detalle!$S$2:$S$521) -> Santander Digital Services | R40: =LOOKUP(C40,[2]APMT_Detalle!$B$2:$B$521,[2]APMT_Detalle!$AP$2:$AP$521) -> External
...

Sheet Stakeholders
A1: Tool Id | B1: Business Unit Name | C1: Application Name | D1: Application Business Owner | E1: Application Technical (IT) Owner | F1: Application Technical Group | G1: Application Technical SPOC | FY1: Field Names
B2: ='Application Info'!B2 -> Surgir | C2: ='Application Info'!C2 -> SAP by Design | D2: DIANA OCHOA CASTILLO | E2: RENZO ALFREDO HUAYLLASCO CÁCERES | FY2: Business_Executive_Sponser
B3: ='Application Info'!B3 -> Surgir | C3: ='Application Info'!C3 -> App Surgir | D3: RENZO ALFREDO HUAYLLASCO CÁCERES | E3: RENZO ALFREDO HUAYLLASCO CÁCERES | FY3: Service_Delivery_Lead
B4: ='Application Info'!B4 -> Surgir | C4: ='Application Info'!C4 -> App Cliente | D4: RENZO ALFREDO HUAYLLASCO CÁCERES | E4: YELTSIN ANTONY ALAN SOTELO CAMONES | FY4: IT_Production_Support_Contact
B5: ='Application Info'!B5 -> Surgir | C5: ='Application Info'!C5 -> AMLUpdate - Name Screening | D5: ALONSO GUILLERMO SERRANO CARMONA | E5: RENZO ALFREDO HUAYLLASCO CÁCERES
B6: ='Application Info'!B6 -> Surgir | C6: ='Application Info'!C6 -> Portal Web Público | D6: RENZO ALFREDO HUAYLLASCO CÁCERES | E6: RENZO ALFREDO HUAYLLASCO CÁCERES
B7: ='Application Info'!B7 -> Surgir | C7: ='Application Info'!C7 -> Anura | D7: ARIANA PEREZ ESCOBAR | E7: RENZO ALFREDO HUAYLLASCO CÁCERES
B8: ='Application Info'!B8 -> Surgir | C8: ='Application Info'!C8 -> ERP Contanet | D8: GABRIELA SOLEDAD LASTARRIA FLORES | E8: RENZO ALFREDO HUAYLLASCO CÁCERES
B9: ='Application Info'!B9 -> Surgir | C9: ='Application Info'!C9 -> Datalake | D9: RENZO ALFREDO HUAYLLASCO CÁCERES | E9: RENZO ALFREDO HUAYLLASCO CÁCERES
B10: ='Application Info'!B10 -> Surgir | C10: ='Application Info'!C10 -> Cobis | D10: RENZO ALFREDO HUAYLLASCO CÁCERES | E10: RENZO ALFREDO HUAYLLASCO CÁCERES
B11: ='Application Info'!B11 -> Santander Fondos Colectivos | C11: ='Application Info'!C11 -> Emblue | D11: Luis Alberto Barandiaran | E11: Luis Alberto Barandiaran
B12: ='Application Info'!B12 -> Santander Fondos Colectivos | C12: ='Application Info'!C12 -> Facephi | D12: Luis Alberto Barandiaran | E12: Luis Alberto Barandiaran
B13: ='Application Info'!B13 -> Santander Fondos Colectivos | C13: ='Application Info'!C13 -> Mapfre | D13: Luis Alberto Barandiaran | E13: LUIS BOULLON GARCIA
B14: ='Application Info'!B14 -> Santander Fondos Colectivos | C14: ='Application Info'!C14 -> Tracklink | D14: Luis Alberto Barandiaran | E14: LUIS BOULLON GARCIA
B15: ='Application Info'!B15 -> Santander Fondos Colectivos | C15: ='Application Info'!C15 -> Docuclass | D15: Luis Alberto Barandiaran | E15: LUIS BOULLON GARCIA
B16: ='Application Info'!B16 -> Santander Fondos Colectivos | C16: ='Application Info'!C16 -> Diloo | D16: Luis Alberto Barandiaran | E16: LUIS BOULLON GARCIA
... B31: ='Application Info'!B31 -> Santander Consumer Perú | C31: ='Application Info'!C31 -> Contáctanos | D31: JESUS DIAZ VALENZUELA | E31: RENZO ALFREDO HUAYLLASCO CÁCERES
B32: ='Application Info'!B32 -> Santander Consumer Perú | C32: ='Application Info'!C32 -> Visor Cobranzas
B33: ='Application Info'!B33 -> Santander Consumer Perú | C33: ='Application Info'!C33 -> Api Market | D33: JESUS DIAZ VALENZUELA | E33: RENZO ALFREDO HUAYLLASCO CÁCERES
B34: ='Application Info'!B34 -> Santander Consumer Perú | C34: ='Application Info'!C34 -> AMLUpdate - Name Screening | D34: ALONSO GUILLERMO SERRANO CARMONA | E34: LUIS BOULLON GARCIA
B35: ='Application Info'!B35 -> Santander Consumer Perú | C35: ='Application Info'!C35 -> Facturación Electrónica - Auto | D35: CHRISTIAN POMAZÓN OBREGÓN | E35: LUIS BOULLON GARCIA
B36: ='Application Info'!B36 -> Santander Consumer Perú | C36: ='Application Info'!C36 -> Portal Web Público | D36: RENZO ALFREDO HUAYLLASCO CÁCERES | E36: LUIS BOULLON GARCIA
B37: ='Application Info'!B37 -> Santander Consumer Perú | C37: ='Application Info'!C37 -> SAP ByDesign - ERP | D37: PATRICIA DIAZ BUSTO | E37: LUIS BOULLON GARCIA
B38: ='Application Info'!B38 -> Santander Consumer Perú | C38: ='Application Info'!C38 -> Bantotal - Core Bancario | D38: JULIO EDUARDO NIÑO SUAREZ | E38: LUIS BOULLON GARCIA
B39: ='Application Info'!B39 -> Santander Consumer Perú | C39: ='Application Info'!C39 -> Motor de Crédito | D39: Darwin Curisinche Rojas | E39: LUIS BOULLON GARCIA
B40: ='Application Info'!B40 -> Santander Consumer Perú | C40: ='Application Info'!C40 -> Santi | D40: IVETTE DEL CARMEN CRUZ VARGAS DEL AGUILA | E40: LUIS BOULLON GARCIA
B41: ='Application Info'!B41 -> Santander Consumer Perú | C41: ='Application Info'!C41 -> Seguros La Positiva | D41: JULIO EDUARDO NIÑO SUAREZ | E41: LUIS BOULLON GARCIA
B42: ='Application Info'!B42 -> Santander Consumer Perú | C42: ='Application Info'!C42 -> Equifax | D42: Darwin Curisinche Rojas | E42: Darwin Curisinche Rojas
B43: ='Application Info'!B43 -> Santander Consumer Perú | C43: ='Application Info'!C43 -> Docuclass | D43: JULIO EDUARDO NIÑO SUAREZ | E43: LUIS BOULLON GARCIA
B44: ='Application Info'!B44 -> Santander Consumer Perú | C44: ='Application Info'!C44 -> Seir | D44: PATRICIA DIAZ BUSTO | E44: LUIS BOULLON GARCIA
B45: ='Application Info'!B45 -> Santander Consumer Perú | C45: ='Application Info'!C45 -> Pomelo
B46: ='Application Info'!B46 -> Santander Consumer Perú | C46: ='Application Info'!C46 -> Izypay
B47: ='Application Info'!B47 -> Santander Consumer Perú | C47: ='Application Info'!C47 -> Kasnet
B48: ='Application Info'!B48 -> Santander Consumer Perú | C48: ='Application Info'!C48 -> ChatBot
B49: ='Application Info'!B49 -> Santander Consumer Perú | C49: ='Application Info'!C49 -> Data Riesgos
B50: ='Application Info'!B50 -> Santander Consumer Perú | C50: ='Application Info'!C50 -> API OTP
B51: ='Application Info'!B51 -> Santander Consumer Perú | C51: ='Application Info'!C51 -> API Portal
B52: ='Application Info'!B52 -> Santander Consumer Perú | C52: ='Application Info'!C52 -> Venta Cartera
B53: ='Application Info'!B53 -> Santander Perú | C53: ='Application Info'!C53 -> Virtual Assistant P&C | D53: LUIS NAVARRO NARVAEZ | E53: ADOLFO UNDA LAZARO
B54: ='Application Info'!B54 -> Santander Perú | C54: ='Application Info'!C54 -> Masterbase | D54: ALEXANDRA DIAZ FIGUEROA | E54: ALFREDO LLONA ARIS
...

Sheet Business Info
A1: Tool Id | B1: Business Unit Name | C1: Application Name | D1: Strategic Business Group (SBG) - mapping from Organization | E1: Line Of Business (LOB)/ Strategic Business Unit (SBU)- mapping from Organization | F1: Application Class | G1: Business Criticality of the Application | H1: Confidentiality Classification | I1: Regulatory Compliance adequacy | J1: Functional Fitness | K1: Business User Satisfaction | L1: Application Owner Insights | FY1: Field Names | FZ1: D,E | GA1: 4 | GB1: <b>Strategic Business Group (SBG) - mapping from Organization</b> | GC1: <b>Line Of Business (LOB)/ Strategic Business Unit (SBU)- mapping from Organization</b> | GD1: <b>Application Class</b> | GE1: <b>Business Criticality of the Application</b> | GF1: <b>Confidentiality Classification</b> | GG1: <b>Regulatory Compliance adequacy</b> | GH1: <b>Functional Fitness</b> | GI1: <b>Business User Satisfaction</b>
B2: ='Application Info'!B2 -> Surgir | C2: ='Application Info'!C2 -> SAP by Design | F2: Tactical | G2: Critical | H2: C2 Internal | FY2: Strategic_bu_group | GA2: 5 | GB2: All | GC2: All | GD2: Strategic | GE2: Critical | GF2: C1 Public | GG2: 1 - Complies fully | GH2: 1-Does not fit at all | GI2: 5 Highest
B3: ='Application Info'!B3 -> Surgir | C3: ='Application Info'!C3 -> App Surgir | F3: technological | G3: Not Applicable | H3: C1 Public | FY3: Line_Of_Business | GD3: Tactical | GE3: High | GF3: C2 Internal | GG3: 1 - Not Applicable / Complies fully | GH3: 2-Below Average - Need major modification | GI3: 4
B4: ='Application Info'!B4 -> Surgir | C4: ='Application Info'!C4 -> App Cliente | F4: Tactical | G4: Critical | H4: C1 Public | FY4: Strategic_Indicator | GD4: Legacy | GE4: Medium | GF4: C3 Confidential | GG4: 2 - Minor Non compliance | GH4: 3-Average - Need moderate modification for business function fitment | GI4: 3
B5: ='Application Info'!B5 -> Surgir | C5: ='Application Info'!C5 -> AMLUpdate - Name Screening | F5: Strategic | G5: Critical | H5: C2 Internal | FY5: Infosec_Classification | GD5: technological | GE5: Not Applicable | GF5: Not Applicable | GG5: 4 - Major Non compliance | GH5: 5-Meets all Business needs | GI5: 1 Lowest
B6: ='Application Info'!B6 -> Surgir | C6: ='Application Info'!C6 -> Portal Web Público | F6: Tactical | G6: Critical | H6: C1 Public | FY6: Regulatory_Compilance | GE6: Unknown | GF6: Unknown | GG6: 5 - Extremely critical non compliance | GH6: Unknown | GI6: Unknown
B7: ='Application Info'!B7 -> Surgir | C7: ='Application Info'!C7 -> Anura | F7: Strategic | G7: Critical | H7: C3 Confidential | FY7: Functional_Fitness | GG7: Unknown
B8: ='Application Info'!B8 -> Surgir | C8: ='Application Info'!C8 -> ERP Contanet | F8: Strategic | G8: Critical | H8: C3 Confidential | FY8: Business_User_satisfication | GG8: Not Applicable
B9: ='Application Info'!B9 -> Surgir | C9: ='Application Info'!C9 -> Datalake | F9: Strategic | G9: Critical | H9: C2 Internal | FY9: Application_Owner_insights | GG9: Not Available
B10: ='Application Info'!B10 -> Surgir | C10: ='Application Info'!C10 -> Cobis | F10: Legacy | G10: Critical | H10: C2 Internal
B11: ='Application Info'!B11 -> Santander Fondos Colectivos | C11: ='Application Info'!C11 -> Emblue | F11: Tactical | G11: Medium | H11: Not Applicable
B12: ='Application Info'!B12 -> Santander Fondos Colectivos | C12: ='Application Info'!C12 -> Facephi | F12: Tactical | G12: Critical | H12: Not Applicable
B13: ='Application Info'!B13 -> Santander Fondos Colectivos | C13: ='Application Info'!C13 -> Mapfre | F13: technological | G13: Medium | H13: C2 Internal
B14: ='Application Info'!B14 -> Santander Fondos Colectivos | C14: ='Application Info'!C14 -> Tracklink | F14: Tactical | G14: Medium | H14: Not Applicable
B15: ='Application Info'!B15 -> Santander Fondos Colectivos | C15: ='Application Info'!C15 -> Docuclass | F15: Tactical | G15: Critical | H15: C2 Internal
B16: ='Application Info'!B16 -> Santander Fondos Colectivos | C16: ='Application Info'!C16 -> Diloo | F16: Tactical | G16: Medium | H16: Not Applicable
B17: ='Application Info'!B17 -> Santander Fondos Colectivos | C17: ='Application Info'!C17 -> Izipay Pagos en línea | F17: Strategic | G17: Critical | H17: C2 Internal
B18: ='Application Info'!B18 -> Santander Fondos Colectivos | C18: ='Application Info'!C18 -> IBK Recaudación | F18: Tactical | G18: Medium | H18: C2 Internal
B19: ='Application Info'!B19 -> Santander Fondos Colectivos | C19: ='Application Info'!C19 -> SAP by Design | F19: Legacy | G19: Critical | H19: C2 Internal
B20: ='Application Info'!B20 -> Santander Fondos Colectivos | C20: ='Application Info'!C20 -> Portal Web Público | F20: Legacy | G20: Critical | H20: C1 Public
B21: ='Application Info'!B21 -> Santander Fondos Colectivos | C21: ='Application Info'!C21 -> AMLUpdate - Name Screening | F21: Strategic | G21: Critical | H21: C2 Internal
... B28: ='Application Info'!B28 -> SCIB Perú | C28: ='Application Info'!C28 -> Sistema Office Banking | F28: Legacy | G28: Critical | H28: C2 Internal
B29: ='Application Info'!B29 -> Santander Consumer Perú | C29: ='Application Info'!C29 -> Diloo | G29: Medium | H29: Not Applicable
B30: ='Application Info'!B30 -> Santander Consumer Perú | C30: ='Application Info'!C30 -> Plataforma de Facturacion Electronica | F30: Strategic | G30: Medium | H30: C2 Internal
B31: ='Application Info'!B31 -> Santander Consumer Perú | C31: ='Application Info'!C31 -> Contáctanos | F31: Tactical | G31: Critical | H31: C1 Public
B32: ='Application Info'!B32 -> Santander Consumer Perú | C32: ='Application Info'!C32 -> Visor Cobranzas | G32: Critical
B33: ='Application Info'!B33 -> Santander Consumer Perú | C33: ='Application Info'!C33 -> Api Market | F33: Tactical | G33: Critical | H33: C2 Internal
B34: ='Application Info'!B34 -> Santander Consumer Perú | C34: ='Application Info'!C34 -> AMLUpdate - Name Screening | G34: Medium | H34: C2 Internal
B35: ='Application Info'!B35 -> Santander Consumer Perú | C35: ='Application Info'!C35 -> Facturación Electrónica - Auto | F35: Strategic | G35: Medium
B36: ='Application Info'!B36 -> Santander Consumer Perú | C36: ='Application Info'!C36 -> Portal Web Público | F36: technological | G36: Critical | H36: C1 Public
B37: ='Application Info'!B37 -> Santander Consumer Perú | C37: ='Application Info'!C37 -> SAP ByDesign - ERP | F37: technological | G37: Critical | H37: C2 Internal
B38: ='Application Info'!B38 -> Santander Consumer Perú | C38: ='Application Info'!C38 -> Bantotal - Core Bancario | F38: Tactical | G38: Critical | H38: C3 Confidential
B39: ='Application Info'!B39 -> Santander Consumer Perú | C39: ='Application Info'!C39 -> Motor de Crédito | F39: Legacy | G39: Critical
B40: ='Application Info'!B40 -> Santander Consumer Perú | C40: ='Application Info'!C40 -> Santi | F40: Legacy | G40: Critical | H40: C2 Internal
B41: ='Application Info'!B41 -> Santander Consumer Perú | C41: ='Application Info'!C41 -> Seguros La Positiva | F41: Legacy | G41: Medium | H41: C2 Internal
B42: ='Application Info'!B42 -> Santander Consumer Perú | C42: ='Application Info'!C42 -> Equifax | F42: Tactical | G42: Medium | H42: Not Applicable
B43: ='Application Info'!B43 -> Santander Consumer Perú | C43: ='Application Info'!C43 -> Docuclass | F43: Legacy | G43: Not Applicable | H43: C2 Internal
B44: ='Application Info'!B44 -> Santander Consumer Perú | C44: ='Application Info'!C44 -> Seir | F44: Strategic | G44: Critical
B45: ='Application Info'!B45 -> Santander Consumer Perú | C45: ='Application Info'!C45 -> Pomelo | F45: Legacy | G45: Medium
B46: ='Application Info'!B46 -> Santander Consumer Perú | C46: ='Application Info'!C46 -> Izypay | F46: Strategic | G46: Critical | H46: Not Applicable
...

Sheet Technical Info
A1: Tool Id | B1: Business Unit Name | C1: Application Name | D1: Region | E1: Hosting | F1: Architecture Style of Application | G1: Presentation Layer Architecture | H1: Integration Architecture | I1: Solutions Technology components/platforms | J1: Virtualisation Support | K1: Application Interfaces (PROVIDERS) | L1: Application Interfaces (CONSUMERS) | M1: Criticality of the interfaces | N1: Application Complexity | O1: Pace Layer classification | GA1: Field Names | GB1: E,F,G | GC1: 5 | GD1: <b>Architecture Style of Application</b> | GE1: <b>Presentation Layer Architecture</b> | GF1: <b>Integration Architecture</b> | GG1: <b>Solutions Technology components/platforms</b> | GH1: <b>Virtualisation Support</b> | GI1: <b>Criticality of the interfaces</b> | GJ1: <b>Application Complexity</b> | GK1: <b>Pace Layer classification</b>
B2: ='Application Info'!B2 -> Surgir | C2: ='Application Info'!C2 -> SAP by Design | D2: =IF(C2='Application Info'!C2,'Application Info'!G2,"N/A") -> Azure | E2: =IF(C2='Application Info'!C2,'Application Info'!H2,"N/A") -> 5. SaaS | F2: Client-server | G2: Web - Thin Client | H2: Service Oriented Integration | I2: SAP PowerBuilder | J2: No | M2: Severe impact | N2: Medium | O2: Unknown | GA2: Architecture_Style | GC2: 6 | GD2: Client-server | GE2: Non Gui - Character oriented | GF2: File Transfer | GG2: ADO.NET | GH2: Yes | GI2: No Interface | GJ2: High | GK2: System of Innovation(SOI)
B3: ='Application Info'!B3 -> Surgir | C3: ='Application Info'!C3 -> App Surgir | D3: =IF(C3='Application Info'!C3,'Application Info'!G3,"N/A") -> Local Country | E3: =IF(C3='Application Info'!C3,'Application Info'!H3,"N/A") -> 3. Hybrid cloud | F3: Not Available | G3: Mobile Client | H3: Service Oriented Integration | J3: No | M3: Moderate impact | N3: Medium | O3: System of Differentiation(SDD) | GA3: Presentation_Layer | GC3: 7 | GD3: Mainframe | GE3: Non Web based Gui | GF3: RPC | GG3: AngularJS | GH3: No | GI3: Minimal Impact | GJ3: Medium | GK3: System of Differentiation(SDD)
B4: ='Application Info'!B4 -> Surgir | C4: ='Application Info'!C4 -> App Cliente | D4: =IF(C4='Application Info'!C4,'Application Info'!G4,"N/A") -> Local Country | E4: =IF(C4='Application Info'!C4,'Application Info'!H4,"N/A") -> 3. Hybrid cloud | F4: Not Available | G4: Mobile Client | H4: Service Oriented Integration | J4: No | M4: Moderate impact | N4: Medium | O4: System of Differentiation(SDD) | GA4: Integration_architecture | GD4: Monolithic | GE4: Web - Thin Client | GF4: Point to Point Message passing | GG4: Apache Tomcat | GH4: Not Available | GI4: Low impact | GJ4: Low | GK4: System of Record(SOR)
B5: ='Application Info'!B5 -> Surgir | C5: ='Application Info'!C5 -> AMLUpdate - Name Screening | D5: =IF(C5='Application Info'!C5,'Application Info'!G5,"N/A") -> Mexico | E5: =IF(C5='Application Info'!C5,'Application Info'!H5,"N/A") -> 8. On-Premise | F5: Monolithic | G5: Mobile Client | J5: No | GA5: Application_Dev_Tech | GD5: Multi-tier Non Web | GE5: Web - Smart Client / Rich Internet Application | GF5: Message Broker | GG5: Apache Tomcat 6.x | GH5: Not Applicable | GI5: Moderate impact | GJ5: Unknown | GK5: Unknown
B6: ='Application Info'!B6 -> Surgir | C6: ='Application Info'!C6 -> Portal Web Público | D6: =IF(C6='Application Info'!C6,'Application Info'!G6,"N/A") -> Local Country | E6: =IF(C6='Application Info'!C6,'Application Info'!H6,"N/A") -> 8. On-Premise | F6: Monolithic | G6: Web - Thin Client | J6: No | GA6: Virtualisation_support | GD6: SaaS / Cloud based | GE6: Mobile Client | GF6: Workflow based | GG6: Apache Tomcat 7.x | GI6: Severe impact | GJ6: Not Available | GK6: Not Available
B7: ='Application Info'!B7 -> Surgir | C7: ='Application Info'!C7 -> Anura | D7: =IF(C7='Application Info'!C7,'Application Info'!G7,"N/A") -> Local Country | E7: =IF(C7='Application Info'!C7,'Application Info'!H7,"N/A") -> 5. SaaS | F7: Monolithic | G7: Web - Thin Client | J7: No | GA7: App_Interface_Providers | GD7: Service Oriented | GE7: Terminal Services / VDI | GF7: Content Collaboration | GG7: Apache Tomcat 8.x | GI7: Unknown | GK7: Not Applicable
B8: ='Application Info'!B8 -> Surgir | C8: ='Application Info'!C8 -> ERP Contanet | D8: =IF(C8='Application Info'!C8,'Application Info'!G8,"N/A") -> Azure | E8: =IF(C8='Application Info'!C8,'Application Info'!H8,"N/A") -> 5. SaaS | F8: Monolithic | G8: Mobile Client | J8: No | GA8: App_Interface_Consumers | GD8: Web based Multi tier | GE8: Multichannel integrated - Mobile GUI / IVR / Social network support | GF8: Not Available | GG8: Apache Web Server | GI8: Not Applicable
B9: ='Application Info'!B9 -> Surgir | C9: ='Application Info'!C9 -> Datalake | D9: =IF(C9='Application Info'!C9,'Application Info'!G9,"N/A") -> Local Country | E9: =IF(C9='Application Info'!C9,'Application Info'!H9,"N/A") -> 3. Hybrid cloud | F9: Monolithic | G9: Web - Thin Client | H9: Data Feed/ ETL / Batch | J9: No | M9: Moderate impact | N9: High | O9: System of Record(SOR) | GA9: Criticality_Interface | GD9: Component Based | GE9: Not Available | GF9: Point to Point through shared database | GG9: Apache Web Server 2.0 | GI9: Not Available
B10: ='Application Info'!B10 -> Surgir | C10: ='Application Info'!C10 -> Cobis | D10: =IF(C10='Application Info'!C10,'Application Info'!G10,"N/A") -> AWS | E10: =IF(C10='Application Info'!C10,'Application Info'!H10,"N/A") -> 3. Hybrid cloud | F10: Monolithic | G10: Web - Thin Client | H10: Data Feed/ ETL / Batch | J10: No | M10: Severe impact | N10: High | O10: System of Record(SOR) | GA10: Application_Complexity | GD10: Not Available | GE10: Not Applicable | GF10: Data Feed/ ETL / Batch | GG10: Apache Web Server 2.2
B11: ='Application Info'!B11 -> Santander Fondos Colectivos | C11: ='Application Info'!C11 -> Emblue | D11: =IF(C11='Application Info'!C11,'Application Info'!G11,"N/A") -> Local Country | E11: =IF(C11='Application Info'!C11,'Application Info'!H11,"N/A") -> 7.Vendor sit | F11: Service Oriented | G11: Web - Smart Client / Rich Internet Application | H11: Service Oriented Integration | J11: No | M11: Low impact | N11: Medium | O11: System of Innovation(SOI) | GA11: Pace_Layer | GF11: Service Oriented Integration | GG11: Apache Web Server 2.4
B12: ='Application Info'!B12 -> Santander Fondos Colectivos | C12: ='Application Info'!C12 -> Facephi | D12: =IF(C12='Application Info'!C12,'Application Info'!G12,"N/A") -> Local Country | E12: =IF(C12='Application Info'!C12,'Application Info'!H12,"N/A") -> 7.Vendor sit | F12: Service Oriented | G12: Web - Smart Client / Rich Internet Application | H12: Service Oriented Integration | J12: No | M12: Moderate impact | N12: High | O12: System of Innovation(SOI) | GF12: EDI (Electronic Data Interchange) | GG12: Aspose Total 1.0
B13: ='Application Info'!B13 -> Santander Fondos Colectivos | C13: ='Application Info'!C13 -> Mapfre | D13: =IF(C13='Application Info'!C13,'Application Info'!G13,"N/A") -> Local Country | E13: =IF(C13='Application Info'!C13,'Application Info'!H13,"N/A") -> 5. SaaS | F13: Not Available | G13: Non Web based Gui | H13: Point to Point Message passing | J13: No | M13: Minimal Impact | N13: Low | GF13: Integration-as-a-Service | GG13: Bootstrap
B14: ='Application Info'!B14 -> Santander Fondos Colectivos | C14: ='Application Info'!C14 -> Tracklink | D14: =IF(C14='Application Info'!C14,'Application Info'!G14,"N/A") -> Local Country | E14: =IF(C14='Application Info'!C14,'Application Info'!H14,"N/A") -> 7.Vendor sit | F14: Service Oriented | G14: Web - Smart Client / Rich Internet Application | H14: Service Oriented Integration | J14: No | M14: Low impact | N14: Medium | O14: System of Innovation(SOI) | GF14: No Integration / Standalone | GG14: Citrix XenApp 6.5
B15: ='Application Info'!B15 -> Santander Fondos Colectivos | C15: ='Application Info'!C15 -> Docuclass | D15: =IF(C15='Application Info'!C15,'Application Info'!G15,"N/A") -> Local Country | E15: =IF(C15='Application Info'!C15,'Application Info'!H15,"N/A") -> 8. On-Premise | F15: Monolithic | G15: Web - Smart Client / Rich Internet Application | H15: Service Oriented Integration | J15: No | M15: Low impact | N15: Medium | O15: System of Innovation(SOI) | GF15: Not Applicable | GG15: Citrix XenApp Terminal Services
B16: ='Application Info'!B16 -> Santander Fondos Colectivos | C16: ='Application Info'!C16 -> Diloo | D16: =IF(C16='Application Info'!C16,'Application Info'!G16,"N/A") -> US | E16: =IF(C16='Application Info'!C16,'Application Info'!H16,"N/A") -> 7.Vendor sit | F16: Client-server | G16: Web - Smart Client / Rich Internet Application | H16: Service Oriented Integration | J16: No | M16: Low impact | N16: Medium | O16: System of Innovation(SOI) | GG16: Citrix XenMobile 10.x
B17: ='Application Info'!B17 -> Santander Fondos Colectivos | C17: ='Application Info'!C17 -> Izipay Pagos en línea | D17: =IF(C17='Application Info'!C17,'Application Info'!G17,"N/A") -> Local Country | E17: =IF(C17='Application Info'!C17,'Application Info'!H17,"N/A") -> 3. Hybrid cloud | F17: Monolithic | G17: Web - Smart Client / Rich Internet Application | H17: Point to Point Message passing | I17: JBoss 5.1 | J17: No | M17: Severe impact | N17: High | O17: Unknown | GG17: Cordova 1.0
B18: ='Application Info'!B18 -> Santander Fondos Colectivos | C18: ='Application Info'!C18 -> IBK Recaudación | D18: =IF(C18='Application Info'!C18,'Application Info'!G18,"N/A") -> Local Country | E18: =IF(C18='Application Info'!C18,'Application Info'!H18,"N/A") -> 8. On-Premise | F18: Service Oriented | G18: Not Available | H18: Point to Point Message passing | I18: JBoss 5.1 | J18: No | M18: Severe impact | N18: High | O18: Unknown | GG18: Eclipse
B19: ='Application Info'!B19 -> Santander Fondos Colectivos | C19: ='Application Info'!C19 -> SAP by Design | D19: =IF(C19='Application Info'!C19,'Application Info'!G19,"N/A") -> Mexico | E19: =IF(C19='Application Info'!C19,'Application Info'!H19,"N/A") -> 5. SaaS | F19: Service Oriented | G19: Not Applicable | H19: Integration-as-a-Service | J19: No | M19: Severe impact | N19: High | O19: Not Available | GG19: IBM Rational Application Developer
B20: ='Application Info'!B20 -> Santander Fondos Colectivos | C20: ='Application Info'!C20 -> Portal Web Público | D20: =IF(C20='Application Info'!C20,'Application Info'!G20,"N/A") -> Mexico | E20: =IF(C20='Application Info'!C20,'Application Info'!H20,"N/A") -> 8. On-Premise | F20: Service Oriented | G20: Web - Thin Client | H20: Service Oriented Integration | J20: No | M20: Severe impact | N20: High | O20: System of Innovation(SOI) | GG20: Java Runtime 6
B21: ='Application Info'!B21 -> Santander Fondos Colectivos | C21: ='Application Info'!C21 -> AMLUpdate - Name Screening | D21: =IF(C21='Application Info'!C21,'Application Info'!G21,"N/A") -> Local Country | E21: =IF(C21='Application Info'!C21,'Application Info'!H21,"N/A") -> 5. SaaS | F21: Service Oriented | G21: Non Web based Gui | H21: Integration-as-a-Service | J21: No | M21: Severe impact | N21: High | O21: Not Applicable | GG21: JBoss 5.1
B22: ='Application Info'!B22 -> Santander Fondos Colectivos | C22: ='Application Info'!C22 -> Santo | D22: =IF(C22='Application Info'!C22,'Application Info'!G22,"N/A") -> Local Country | E22: =IF(C22='Application Info'!C22,'Application Info'!H22,"N/A") -> 3. Hybrid cloud | F22: SaaS / Cloud based | G22: Web - Thin Client | H22: Service Oriented Integration | J22: No | M22: Severe impact | N22: High | O22: System of Record(SOR) | GG22: Kendo UI
B23: ='Application Info'!B23 -> SCIB Perú | C23: ='Application Info'!C23 -> Nuevo Office Banking | D23: =IF(C23='Application Info'!C23,'Application Info'!G23,"N/A") -> US | E23: =IF(C23='Application Info'!C23,'Application Info'!H23,"N/A") -> 5. SaaS | F23: SaaS / Cloud based | G23: Web - Thin Client | H23: Service Oriented Integration | J23: No | M23: Severe impact | N23: High | O23: System of Innovation(SOI) | GG23: Microsoft .NET Framework
B24: ='Application Info'!B24 -> SCIB Perú | C24: ='Application Info'!C24 -> CEEFFC | D24: =IF(C24='Application Info'!C24,'Application Info'!G24,"N/A") -> Mexico | E24: =IF(C24='Application Info'!C24,'Application Info'!H24,"N/A") -> 8. On-Premise | F24: Monolithic | G24: Non Web based Gui | H24: Integration-as-a-Service | J24: No | M24: Severe impact | N24: High | O24: Not Applicable | GG24: Microsoft .NET Framework 2.0
B25: ='Application Info'!B25 -> SCIB Perú | C25: ='Application Info'!C25 -> Lbtr | D25: =IF(C25='Application Info'!C25,'Application Info'!G25,"N/A") -> Local Country | E25: =IF(C25='Application Info'!C25,'Application Info'!H25,"N/A") -> 8. On-Premise | F25: Service Oriented | G25: Not Available | H25: Point to Point Message passing | I25: JBoss 5.1 | J25: No | M25: Severe impact | N25: High | O25: Unknown | GG25: Microsoft .NET Framework 3.5
B26: ='Application Info'!B26 -> SCIB Perú | C26: ='Application Info'!C26 -> Cash Nexus | D26: =IF(C26='Application Info'!C26,'Application Info'!G26,"N/A") -> Local Country | E26: =IF(C26='Application Info'!C26,'Application Info'!H26,"N/A") -> 3. Hybrid cloud | F26: Client-server | G26: Non Web based Gui | H26: Integration-as-a-Service | J26: No | M26: Severe impact | N26: High | O26: Not Applicable | GG26: Microsoft .NET Framework 4.0
B27: ='Application Info'!B27 -> SCIB Perú | C27: ='Application Info'!C27 -> Host to Host | D27: =IF(C27='Application Info'!C27,'Application Info'!G27,"N/A") -> Local Country | E27: =IF(C27='Application Info'!C27,'Application Info'!H27,"N/A") -> 8. On-Premise | F27: Service Oriented | G27: Not Available | H27: Point to Point Message passing | I27: JBoss 5.1 | J27: No | M27: Severe impact | N27: High | O27: Unknown | GG27: Microsoft .NET Framework 4.5
B28: ='Application Info'!B28 -> SCIB Perú | C28: ='Application Info'!C28 -> Sistema Office Banking | D28: =IF(C28='Application Info'!C28,'Application Info'!G28,"N/A") -> Azure | E28: =IF(C28='Application Info'!C28,'Application Info'!H28,"N/A") -> 3. Hybrid cloud | F28: Service Oriented | G28: Web - Thin Client | H28: Service Oriented Integration | J28: No | M28: Severe impact | N28: High | O28: System of Innovation(SOI) | GG28: Microsoft .NET Framework 4.5.1
B29: ='Application Info'!B29 -> Santander Consumer Perú | C29: ='Application Info'!C29 -> Diloo | D29: =IF(C29='Application Info'!C29,'Application Info'!G29,"N/A") -> US | E29: =IF(C29='Application Info'!C29,'Application Info'!H29,"N/A") -> 7.Vendor sit | F29: Web based Multi tier | G29: Web - Smart Client / Rich Internet Application | H29: Service Oriented Integration | J29: No | M29: Low impact | N29: Medium | O29: System of Innovation(SOI) | GG29: Microsoft .NET Framework 4.5.2
B30: ='Application Info'!B30 -> Santander Consumer Perú | C30: ='Application Info'!C30 -> Plataforma de Facturacion Electronica | D30: =IF(C30='Application Info'!C30,'Application Info'!G30,"N/A") -> AWS | E30: =IF(C30='Application Info'!C30,'Application Info'!H30,"N/A") -> 8. On-Premise | F30: SaaS / Cloud based | G30: Web - Thin Client | H30: Point to Point Message passing | J30: No | M30: Moderate impact | N30: Medium | GG30: Microsoft Active Directory Domain Services 1.0
B31: ='Application Info'!B31 -> Santander Consumer Perú | C31: ='Application Info'!C31 -> Contáctanos | D31: =IF(C31='Application Info'!C31,'Application Info'!G31,"N/A") -> Local Country | E31: =IF(C31='Application Info'!C31,'Application Info'!H31,"N/A") -> 6. Sharepoint | F31: Monolithic | G31: Web - Thin Client | H31: Service Oriented Integration | J31: No | M31: Minimal Impact | N31: Low | O31: Not Applicable | GG31: Microsoft Active Directory Federation Services 2012 R2
